Workbook

Sheet Dashboard
A1: AST SPACEMOBILE (NASDAQ: ASTS) - INTRINSIC VALUATION MODEL
A2: Valuation date 10-Sep-2026. USD. Balance sheet 30-Jun-2026 pro forma Jul-2026 convertible. Live links unless marked 'stamped'.
A4: MODEL STATUS | B4: =Checks!$C$3 -> ALL PASS
A6: Headline
A7: Current share price (IBKR) | B7: =Market_Data!$J$7 -> 62.42
A8: Probability-weighted intrinsic value | B8: =Valuation_Summary!F11 -> 52.878954
A9: Upside / (downside) vs price | B9: =Valuation_Summary!F11/Market_Data!$J$7-1 -> -0.15285239
A10: Monte Carlo mean (stamped) | B10: =Monte_Carlo!$B$36 -> 55.230451
A11: Monte Carlo P10 - P90 (stamped) | B11: =TEXT(Monte_Carlo!$B$39,"$0")&" - "&TEXT(Monte_Carlo!$B$43,"$0") -> $0 - $128
A12: P(intrinsic value > price) (stamped) | B12: =Monte_Carlo!$B$45 -> 0.3456
A13: Model-implied expected return p.a., 3-yr (prob-weighted) | B13: =Valuation_Summary!F24 -> 0.045555578
A14: Model-implied expected return p.a., 3-yr (MC mean) | B14: =Monte_Carlo!$B$51 -> 0.060829775
A15: Realised volatility (annualised) | B15: =Market_Data!$J$14 -> 0.93751899
A16: Growth-phase WACC / terminal WACC | B16: =TEXT(WACC!$C$11,"0.0%")&" / "&TEXT(WACC!$C$16,"0.0%") -> 10.3% / 8.3%
A17: Market-implied Base Tier-1 take rate (stamped reverse DCF) | B17: 0.10635771
A19: Scenarios (live)
B20: Distress | C20: Bear | D20: Base | E20: Bull | F20: Weighted
A21: Probability | B21: =Valuation_Summary!B5 -> 0.15 | C21: =Valuation_Summary!C5 -> 0.25 | D21: =Valuation_Summary!D5 -> 0.4 | E21: =Valuation_Summary!E5 -> 0.2 | F21: =Valuation_Summary!F5 -> 1
A22: Value per share ($) | B22: =Valuation_Summary!B11 -> 0 | C22: =Valuation_Summary!C11 -> 1.1878934 | D22: =Valuation_Summary!D11 -> 57.398181 | E22: =Valuation_Summary!E11 -> 148.11354 | F22: =Valuation_Summary!F11 -> 52.878954
A23: Enterprise value ($mm) | B23: =Valuation_Summary!B6 -> -12156.033 | C23: =Valuation_Summary!C6 -> 889.33938 | D23: =Valuation_Summary!D6 -> 23596.959 | E23: =Valuation_Summary!E6 -> 61532.382
A24: Revenue 2030 ($mm) | B24: =Valuation_Summary!B13 -> 196.85866 | C24: =Valuation_Summary!C13 -> 900.41765 | D24: =Valuation_Summary!D13 -> 3252.7922 | E24: =Valuation_Summary!E13 -> 7616.6973
A25: Revenue 2035 ($mm) | B25: =Valuation_Summary!B14 -> 630.97518 | C25: =Valuation_Summary!C14 -> 2754.0556 | D25: =Valuation_Summary!D14 -> 5926.9154 | E25: =Valuation_Summary!E14 -> 11462.384
A26: EBITDA margin 2040 | B26: =Valuation_Summary!B15 -> -0.56379242 | C26: =Valuation_Summary!C15 -> 0.45040789 | D26: =Valuation_Summary!D15 -> 0.63829787 | E26: =Valuation_Summary!E15 -> 0.72668415
A27: Peak funding need ($mm) | B27: =Valuation_Summary!B17 -> -13563.687 | C27: =Valuation_Summary!C17 -> -5827.8503 | D27: =Valuation_Summary!D17 -> -3413.2802 | E27: =Valuation_Summary!E17 -> -2121.0043
A29: For the portfolio analysis
A30: The earlier portfolio work used a 12% expected return for ASTS as an explicit placeholder guess.
A31: This model replaces it with the model-implied figures above: expected return and volatility for the ASTS sleeve.
A32: Interpretation: at today's price the market is paying roughly for Base-case execution; the payoff is highly skewed
A33: (meaningful probability of ~zero equity value, long right tail). Not investment advice.

Sheet Valuation_Summary
A1: VALUATION SUMMARY
A2: Probability-weighted DCF across four scenarios (all live). USD.
A4: Metric | B4: Distress | C4: Bear | D4: Base | E4: Bull | F4: Prob-weighted
A5: Probability | B5: =Inputs!D57 -> 0.15 | C5: =Inputs!E57 -> 0.25 | D5: =Inputs!F57 -> 0.4 | E5: =Inputs!G57 -> 0.2 | F5: =SUM(B5:E5) -> 1
A6: Enterprise value ($mm) | B6: =Calc_Distress!$C$87 -> -12156.033 | C6: =Calc_Bear!$C$87 -> 889.33938 | D6: =Calc_Base!$C$87 -> 23596.959 | E6: =Calc_Bull!$C$87 -> 61532.382
A7: PV of terminal value ($mm) | B7: =Calc_Distress!$C$85 -> -3888.1316 | C7: =Calc_Bear!$C$85 -> 3615.5397 | D7: =Calc_Base!$C$85 -> 14896.304 | E7: =Calc_Bull!$C$85 -> 34477.442
A8: Terminal value % of EV | B8: =Calc_Distress!$C$88 -> 0 | C8: =Calc_Bear!$C$88 -> 4.0654218 | D8: =Calc_Base!$C$88 -> 0.63128067 | E8: =Calc_Bull!$C$88 -> 0.56031379
A9: Equity before conversions ($mm) | B9: =Calc_Distress!$C$94 -> -12572.982 | C9: =Calc_Bear!$C$94 -> 472.39038 | D9: =Calc_Base!$C$94 -> 23180.01 | E9: =Calc_Bull!$C$94 -> 61115.433
A10: Diluted shares (mm) | B10: =Calc_Distress!$C$108 -> 389.16749 | C10: =Calc_Bear!$C$108 -> 402.19475 | D10: =Calc_Base!$C$108 -> 404.33827 | E10: =Calc_Bull!$C$108 -> 430.03296
A11: Value per share ($) | B11: =Calc_Distress!$C$109 -> 0 | C11: =Calc_Bear!$C$109 -> 1.1878934 | D11: =Calc_Base!$C$109 -> 57.398181 | E11: =Calc_Bull!$C$109 -> 148.11354 | F11: =SUMPRODUCT($B$5:$E$5,B11:E11) -> 52.878954
A12: Upside vs price | B12: =Calc_Distress!$C$110 -> -1 | C12: =Calc_Bear!$C$110 -> -0.98096935 | D12: =Calc_Base!$C$110 -> -0.080452089 | E12: =Calc_Bull!$C$110 -> 1.3728539
A13: Revenue 2030 ($mm) | B13: =Calc_Distress!$C$117 -> 196.85866 | C13: =Calc_Bear!$C$117 -> 900.41765 | D13: =Calc_Base!$C$117 -> 3252.7922 | E13: =Calc_Bull!$C$117 -> 7616.6973
A14: Revenue 2035 ($mm) | B14: =Calc_Distress!$C$118 -> 630.97518 | C14: =Calc_Bear!$C$118 -> 2754.0556 | D14: =Calc_Base!$C$118 -> 5926.9154 | E14: =Calc_Bull!$C$118 -> 11462.384
A15: EBITDA margin 2040 | B15: =Calc_Distress!$C$116 -> -0.56379242 | C15: =Calc_Bear!$C$116 -> 0.45040789 | D15: =Calc_Base!$C$116 -> 0.63829787 | E15: =Calc_Bull!$C$116 -> 0.72668415
A16: Implied terminal EV/EBITDA | B16: =Calc_Distress!$C$89 -> n/m | C16: =Calc_Bear!$C$89 -> 8.4252855 | D16: =Calc_Base!$C$89 -> 11.708219 | E16: =Calc_Bull!$C$89 -> 12.323268
A17: Peak funding need, cumulative FCFF ($mm) | B17: =Calc_Distress!$C$113 -> -13563.687 | C17: =Calc_Bear!$C$113 -> -5827.8503 | D17: =Calc_Base!$C$113 -> -3413.2802 | E17: =Calc_Bull!$C$113 -> -2121.0043
A18: Max paying users per satellite (mm) | B18: =Calc_Distress!$C$114 -> 0.35777866 | C18: =Calc_Bear!$C$114 -> 1.0043034 | D18: =Calc_Base!$C$114 -> 1.8197635 | E18: =Calc_Bull!$C$114 -> 2.1552533
A19: FY2026 revenue ($mm) | B19: =Calc_Distress!$C$112 -> 151.255 | C19: =Calc_Bear!$C$112 -> 166.255 | D19: =Calc_Base!$C$112 -> 174.955 | E19: =Calc_Bull!$C$112 -> 186.255
A21: Current share price ($, IBKR) | F21: =Market_Data!$J$7 -> 62.42
A22: Probability-weighted upside / (downside) | F22: =F11/F21-1 -> -0.15285239
A23: Growth-phase cost of equity (Ke) | F23: =WACC!$C$8 -> 0.10499614
A24: Model-implied expected return p.a. if price converges to value in 3 yrs | F24: =IF(F11<=0,-1,(F11*(1+F23)^3/F21)^(1/3)-1) -> 0.045555578 | G24: E[R] = (V x (1+Ke)^H / P)^(1/H) - 1. Replaces the 12% placeholder in the portfolio analysis.
A25: Model-implied expected return p.a. if price converges to value in 5 yrs | F25: =IF(F11<=0,-1,(F11*(1+F23)^5/F21)^(1/5)-1) -> 0.068938152 | G25: E[R] = (V x (1+Ke)^H / P)^(1/H) - 1. Replaces the 12% placeholder in the portfolio analysis.
A26: Market-implied EV ($mm) | F26: =Capital_Structure!$B$61 -> 24708.784
A27: Base-case EV / market-implied EV | F27: =D6/Capital_Structure!$B$61 -> 0.95500283

Sheet Inputs
A1: INPUTS & ASSUMPTIONS
A2: Blue = hard-coded input (edit here only). Yellow = key value driver. Every formula in the model references this sheet. Units in column C. $mm unless stated.
A4: Key | B4: Global parameter | C4: Unit | D4: Value | H4: Source / rationale
A5: VALUATION & MARKET
A6: val_date | B6: Valuation date (year fraction) | C6: yr | D6: 2026.69 | H6: DATA: 10-Sep-2026 = 2026 + 252/365.
A7: rf | B7: Risk-free rate (10y UST) | C7: % | D7: 0.0484 | H7: DATA: 10y UST 4.84% on 10-Sep-2026 (TradingEconomics / CNBC).
A8: erp | B8: Equity risk premium (US implied) | C8: % | D8: 0.0442 | H8: DATA: Damodaran implied US ERP 4.42% at 1-Jul-2026 (Musings on Markets, Jul-2026).
A9: blume_w | B9: Blume weight on raw beta | C9: x | D9: 0.67 | H9: METHOD: Blume (1971) adjustment beta_adj = 0.67*raw + 0.33. Resolution R-01.
A10: dv_hi | B10: Debt / capital - growth phase | C10: % | D10: 0.15 | H10: DATA-DERIVED: ~$4.2bn debt face vs ~$24.3bn equity mkt cap (Sep-2026) = 14.6%.
A11: kd_hi | B11: Pre-tax cost of straight debt - growth phase | C11: % | D11: 0.095 | H11: ASSUMPTION: unrated issuer; straight-bond yield ~Rf+4.7%. Converts' coupons understate cost (embedded option).
A12: t_hi | B12: Tax rate in WACC - growth phase | C12: % | D12: 0 | H12: LOGIC: no cash taxes paid while loss-making (NOLs/bonus depreciation) -> no interest tax shield.
A13: beta_term | B13: Beta - mature phase | C13: x | D13: 1 | H13: ASSUMPTION: mature satellite operator converges to market beta (Damodaran young-firm lifecycle method).
A14: dv_term | B14: Debt / capital - mature phase | C14: % | D14: 0.25 | H14: ASSUMPTION: mature telecom-like leverage.
A15: kd_term | B15: Pre-tax cost of debt - mature phase | C15: % | D15: 0.07 | H15: ASSUMPTION: BB-area mature issuer.
A16: t_term | B16: Tax rate in WACC - mature phase | C16: % | D16: 0.25 | H16: Equals cash tax rate.
A17: wacc_fade_start | B17: WACC fade start year | C17: yr | D17: 2031 | H17: ASSUMPTION: fade begins after build-out.
... A20: g | B20: Terminal growth (nominal) | C20: % | D20: 0.025 | H20: ASSUMPTION: <= long-run nominal GDP and < Rf (checked).
A21: OPERATIONS (all scenarios)
A22: tax_rate | B22: Cash tax rate (fed 21% + state) | C22: % | D22: 0.25 | H22: ASSUMPTION: 21% federal + ~4% blended state.
A23: nol_open | B23: Opening tax NOL pool (30-Jun-2026) | C23: $mm | D23: 1000 | H23: ASSUMPTION (flagged): accumulated deficit $1,253.6mm (10-Q) includes non-deductible items; haircut to $1.0bn.
A24: nol_limit | B24: NOL usage cap (% of taxable income) | C24: % | D24: 0.8 | H24: LAW: post-TCJA federal 80% limitation.
A25: bonus_dep | B25: 100% bonus depreciation on capex (1=on) | C25: flag | D25: 1 | H25: LAW: OBBBA (Jul-2025) permanently restored 100% bonus depreciation. Verify with tax adviser.
A26: sat_life | B26: Block 2 satellite design life | C26: yrs | D26: 7 | H26: SECONDARY DATA: 7-yr lifetime per Gunter's Space Page (BlueBird Block 2). Flagged for confirmation.
A27: loss_rate | B27: Launch / early-life loss rate | C27: % | D27: 0.05 | H27: ASSUMPTION: 1 of 8 Block 2 lost (BB7, Apr-2026) = 12.5% observed; industry mature ~3-5%.
A28: fleet_open | B28: Block 2 satellites launched at 30-Jun-2026 | C28: # | D28: 4 | H28: DATA: BB6 (Dec-2025) + BB8-10 (17-Jun-2026). BB7 lost. (10-Q Note 1)
A29: cip_sat | B29: Satellite CIP / advance launch payments 30-Jun-2026 | C29: $mm | D29: 1724.085 | H29: DATA: 10-Q Note 4, 'Satellite materials ... advance launch payments'.
A30: partner_subs | B30: MNO partner subscriber base | C30: mm | D30: 3000 | H30: DATA: company - 60+ MNO partners covering 'over 3 billion' subscribers (Q2-26 deck).
A31: t1_share | B31: Share of partner base in Tier-1 (developed) markets | C31: % | D31: 0.25 | H31: ASSUMPTION: US/Canada/Europe/Japan/Gulf partners ~ 750mm of 3bn.
A32: s0_t1 | B32: Tier-1 coverage starts at fleet of | C32: # | D32: 20 | H32: ASSUMPTION: intermittent service below ~20.
A33: sf_t1 | B33: Tier-1 continuous coverage at fleet of | C33: # | D33: 60 | H33: DATA: mgmt '~45-60 BlueBirds' for continuous US/Europe/Japan service (Q2-26 call); upper end used.
... A53: gov_cogs | B53: Government revenue COGS % | C53: % | D53: 0.35 | H53: ASSUMPTION: Q2-26 services COGS 16%; normalised higher at scale.
A55: Key | B55: Scenario parameter | C55: Unit | D55: Distress | E55: Bear | F55: Base | G55: Bull | H55: Source / rationale
A56: SCENARIO PROBABILITIES
A57: prob | B57: Scenario probability | C57: % | D57: 0.15 | E57: 0.25 | F57: 0.4 | G57: 0.2 | H57: ASSUMPTION: Distress reflects failure-to-scale/competitive loss; must sum to 100% (checked).
A58: CONSTELLATION DEPLOYMENT (Block 2 in orbit, end of period)
A59: fl_26 | B59: Fleet end-2026 | C59: # | D59: 15 | E59: 20 | F59: 25 | G59: 35 | H59: DATA anchor: 7 in orbit Aug-2026; mgmt target ~45 in early 2027. Base haircuts for BB7 loss / slip history.
A60: fl_27 | B60: Fleet end-2027 | C60: # | D60: 30 | E60: 45 | F60: 60 | G60: 75 | H60: ASSUMPTION.
A61: fl_28 | B61: Fleet end-2028 | C61: # | D61: 45 | E61: 60 | F61: 90 | G61: 100 | H61: ASSUMPTION.
A62: fl_29 | B62: Fleet end-2029 | C62: # | D62: 45 | E62: 75 | F62: 90 | G62: 110 | H62: ASSUMPTION.
A63: fl_ss | B63: Steady-state fleet (2030+) | C63: # | D63: 45 | E63: 90 | F63: 90 | G63: 120 | H63: ASSUMPTION: Distress = cannot fund beyond ~45.
...

Sheet Capital_Structure
A1: CAPITAL STRUCTURE & EQUITY BRIDGE INPUTS
A2: Balance sheet at 30-Jun-2026 (10-Q) pro forma for the Jul-2026 $1.15bn 2034 convertible. Share count at 6-Aug-2026. $mm; shares in mm unless stated.
A4: Share count (economic interests)
A5: Class | B5: Shares | G5: Source
A6: Class A common (6-Aug-2026) | B6: 299789305 | G6: 10-Q cover page
A7: Class B common = AST LLC units (exchangeable 1:1) | B7: 11215111 | G7: 10-Q cover page
A8: Class C common = AST LLC units (exchangeable 1:1) | B8: 78163078 | G8: 10-Q cover page
A9: Basic economic shares (mm) - S0 | B9: =SUM(B6:B8)/1000000 -> 389.16749 | G9: Up-C: Class B/C are voting-only; economics sit in AST LLC units exchangeable 1:1 (R-05).
A11: Cash & liquid assets
A12: Item | B12: $mm | C12: Include (1/0) | D12: Included $mm
A13: Cash & cash equivalents (30-Jun-2026) | B13: 2288.253 | C13: 1 | D13: =B13*C13 -> 2288.253 | G13: 10-Q balance sheet
A14: Restricted cash - non-current (UBS bridge collateral) | B14: 428.4 | C14: 1 | D14: =B14*C14 -> 428.4 | G14: 10-Q Note 3; nets vs UBS loan
A15: Restricted cash - current (LC/customs collateral) | B15: 6.181 | C15: 0 | D15: =B15*C15 -> 0 | G15: 10-Q; excluded - not available
A16: 2034 notes gross proceeds (Jul-2026, $1.15bn) | B16: 1150 | C16: 1 | D16: =B16*C16 -> 1150 | G16: 8-K / PR 21-Jul-2026
A17: less: discounts & expenses | B17: -18.8 | C17: 1 | D17: =B17*C17 -> -18.8 | G17: Net proceeds $1,131.2mm (pricing PR)
A18: less: capped-call cost (scaled to $1.15bn) | B18: -111.435 | C18: 1 | D18: =B18*C18 -> -111.435 | G18: $96.9mm for $1.0bn (PR) x 1.15 - ESTIMATE
A19: Related-party notes receivable | B19: 18.785 | C19: 1 | D19: =B19*C19 -> 18.785 | G19: 10-Q balance sheet
A20: Total cash & liquid assets | D20: =SUM(D13:D19) -> 3755.203
A21: Check: pro forma cash+restricted vs company-reported 'over $3.7bn' | D21: =D13+D14+B15+D16+D17+D18 -> 3742.599 | G21: Company: 'over $3.7 billion ... pro forma for convertible notes offering' (Q2-26 deck).
A23: Non-convertible debt (face)
A24: Trinity Capital equipment loan | B24: 48.638 | G24: 10-Q Note 6
A25: UBS bridge loan (cash-collateralised) | B25: 420 | G25: 10-Q Note 6
A26: Total non-convertible debt | B26: =SUM(B24:B25) -> 468.638
A28: Convertible notes
A29: Tranche | B29: Face $mm | C29: Conv. price $ | D29: Cap price $ | E29: Shares mm | F29: Trigger K $ | G29: Source
A30: 2032 4.25% converts | B30: 3.514 | C30: 26.99 | D30: 0 | E30: =B30/C30 -> 0.13019637 | F30: =IF(D30>0,D30,C30) -> 26.99 | G30: 10-Q Note 6; conv. rate 37.0535
A31: 2032 2.375% converts | B31: 325 | C31: 72.07 | D31: 0 | E31: =B31/C31 -> 4.5095046 | F31: =IF(D31>0,D31,C31) -> 72.07 | G31: 10-Q Note 6; conv. rate 13.8750 (capped call ignored - conservative)
A32: 2036 2.00% converts | B32: 1150 | C32: 96.3 | D32: 0 | E32: =B32/C32 -> 11.941848 | F32: =IF(D32>0,D32,C32) -> 96.3 | G32: Pricing PR Oct-2025, $96.30
A33: 2036 2.25% converts | B33: 1075 | C33: 116.3 | D33: 0 | E33: =B33/C33 -> 9.2433362 | F33: =IF(D33>0,D33,C33) -> 116.3 | G33: Pricing 8-K Feb-2026, conv. rate 8.5982
A34: 2034 1.625% converts (Jul-2026) | B34: 1150 | C34: 79.57 | D34: 149.2 | E34: =B34/C34 -> 14.452683 | F34: =IF(D34>0,D34,C34) -> 149.2 | G34: Pricing 8-K Jul-2026; capped call cap $149.20
A35: Total convertible face | B35: =SUM(B30:B34) -> 3703.514
A36: Check: total debt face at 30-Jun-2026 vs 10-Q ($3,022.2mm) | B36: =Capital_Structure!$B$26+Capital_Structure!$B$35-B34 -> 3022.152 | G36: 10-Q Note 6 total debt face $3,022,152k (excludes Jul-2026 notes).
A38: Equity awards (treasury-stock logic via value-consistent dilution engine)
A39: Award | B39: Count | C39: Strike $ | G39: Source
A40: 2020 Plan stock options | B40: 1957612 | C40: 9.2 | G40: Q1-26 10-Q (31-Mar-2026, latest disclosed)
A41: 2024 Plan stock options | B41: 55718 | C41: 24.65 | G41: Q2-26 10-Q count; strike = 10-K WAEP
A42: AST LLC incentive options | B42: 5320887 | C42: 1.01 | G42: Q2-25 10-Q (STALE - latest found)
A43: 2020 Plan RSUs | B43: 832699 | C43: 0 | G43: Q2-26 10-Q
A44: 2024 Plan RSUs | B44: 6873666 | C44: 0 | G44: FY25 proxy (STALE, Dec-2025 - latest found)
A46: Dilutive instrument table (feeds every Calc sheet)
...

Sheet WACC
A1: DISCOUNT RATE
A2: CAPM cost of equity; beta estimated live from IBKR data (Market_Data). Growth-phase WACC fades linearly to a mature WACC. Same WACC for every scenario - scenario risk is in cash flows, not the rate (R-03).
A5: Risk-free rate | C5: =Inputs!$D$7 -> 0.0484
A6: Equity risk premium | C6: =Inputs!$D$8 -> 0.0442
A7: Beta - growth phase (Blume-adjusted, live) | C7: =Market_Data!$J$13 -> 1.2804556
A8: Cost of equity - growth phase | C8: =C5+C7*C6 -> 0.10499614
A9: Debt / capital - growth phase | C9: =Inputs!$D$10 -> 0.15
A10: After-tax cost of debt - growth phase | C10: =Inputs!$D$11*(1-Inputs!$D$12) -> 0.095
A11: WACC - growth phase | C11: =(1-C9)*C8+C9*C10+Inputs!$D$19 -> 0.10349672
A12: Beta - mature phase | C12: =Inputs!$D$13 -> 1
A13: Cost of equity - mature phase | C13: =C5+C12*C6 -> 0.0926
A14: Debt / capital - mature phase | C14: =Inputs!$D$14 -> 0.25
A15: After-tax cost of debt - mature phase | C15: =Inputs!$D$15*(1-Inputs!$D$16) -> 0.0525
A16: WACC - mature / terminal | C16: =(1-C14)*C13+C14*C15+Inputs!$D$19 -> 0.082575
A19: Period | D19: 2026H2 | E19: 2027 | F19: 2028 | G19: 2029 | H19: 2030 | I19: 2031 | J19: 2032 | K19: 2033 | L19: 2034 | M19: 2035 | N19: 2036 | O19: 2037 | P19: 2038 | Q19: 2039 | R19: 2040
A20: Year | D20: 2026 | E20: 2027 | F20: 2028 | G20: 2029 | H20: 2030 | I20: 2031 | J20: 2032 | K20: 2033 | L20: 2034 | M20: 2035 | N20: 2036 | O20: 2037 | P20: 2038 | Q20: 2039 | R20: 2040
A21: WACC applied | D21: =IF(D20<Inputs!$D$17,$C$11,IF(D20>=Inputs!$D$18,$C$16,$C$11+($C$16-$C$11)*(D20-Inputs!$D$17+1)/(Inputs!$D$18-Inputs!$D$17+1))) -> 0.10349672 | E21: =IF(E20<Inputs!$D$17,$C$11,IF(E20>=Inputs!$D$18,$C$16,$C$11+($C$16-$C$11)*(E20-Inputs!$D$17+1)/(Inputs!$D$18-Inputs!$D$17+1))) -> 0.10349672 | F21: =IF(F20<Inputs!$D$17,$C$11,IF(F20>=Inputs!$D$18,$C$16,$C$11+($C$16-$C$11)*(F20-Inputs!$D$17+1)/(Inputs!$D$18-Inputs!$D$17+1))) -> 0.10349672 | G21: =IF(G20<Inputs!$D$17,$C$11,IF(G20>=Inputs!$D$18,$C$16,$C$11+($C$16-$C$11)*(G20-Inputs!$D$17+1)/(Inputs!$D$18-Inputs!$D$17+1))) -> 0.10349672 | H21: =IF(H20<Inputs!$D$17,$C$11,IF(H20>=Inputs!$D$18,$C$16,$C$11+($C$16-$C$11)*(H20-Inputs!$D$17+1)/(Inputs!$D$18-Inputs!$D$17+1))) -> 0.10349672 | I21: =IF(I20<Inputs!$D$17,$C$11,IF(I20>=Inputs!$D$18,$C$16,$C$11+($C$16-$C$11)*(I20-Inputs!$D$17+1)/(Inputs!$D$18-Inputs!$D$17+1))) -> 0.099312374 | J21: =IF(J20<Inputs!$D$17,$C$11,IF(J20>=Inputs!$D$18,$C$16,$C$11+($C$16-$C$11)*(J20-Inputs!$D$17+1)/(Inputs!$D$18-Inputs!$D$17+1))) -> 0.095128031 | K21: =IF(K20<Inputs!$D$17,$C$11,IF(K20>=Inputs!$D$18,$C$16,$C$11+($C$16-$C$11)*(K20-Inputs!$D$17+1)/(Inputs!$D$18-Inputs!$D$17+1))) -> 0.090943687 | ... R21: =IF(R20<Inputs!$D$17,$C$11,IF(R20>=Inputs!$D$18,$C$16,$C$11+($C$16-$C$11)*(R20-Inputs!$D$17+1)/(Inputs!$D$18-Inputs!$D$17+1))) -> 0.082575

Sheet Market_Data
A1: MARKET DATA (Interactive Brokers)
A2: Weekly closes, 2-yr window, retrieved from IBKR 10-Sep-2026. ASTS conid 480745767 (NASDAQ), SPY conid 756733 (ARCA). Last bar is a partial week (excluded from regression).
A5: Week start | B5: ASTS close | C5: SPY close | D5: ASTS ret | E5: SPY ret | F5: ASTS peak | G5: Drawdown | I5: Statistic | J5: Value | K5: Note
A6: 2024-09-11 | B6: 29.83 | C6: 562.01 | F6: =B6 -> 29.83 | G6: =B6/F6-1 -> 0
A7: 2024-09-16 | B7: 26.5 | C7: 568.25 | D7: =B7/B6-1 -> -0.11163258 | E7: =C7/C6-1 -> 0.011103005 | F7: =MAX(F6,B7) -> 29.83 | G7: =B7/F7-1 -> -0.11163258 | I7: Current price (last close, $) | J7: =B110 -> 62.42
A8: 2024-09-23 | B8: 25.32 | C8: 571.47 | D8: =B8/B7-1 -> -0.044528302 | E8: =C8/C7-1 -> 0.00566652 | F8: =MAX(F7,B8) -> 29.83 | G8: =B8/F8-1 -> -0.15119008 | I8: Full-week returns in regression (n) | J8: =COUNT(D7:D109) -> 103
A9: 2024-09-30 | B9: 26.11 | C9: 572.98 | D9: =B9/B8-1 -> 0.031200632 | E9: =C9/C8-1 -> 0.0026423084 | F9: =MAX(F8,B9) -> 29.83 | G9: =B9/F9-1 -> -0.12470667 | I9: Raw beta vs SPY (weekly, 2y) | J9: =SLOPE(D7:D109,E7:E109) -> 1.4185905 | K9: 95% CI roughly beta +/- 1.96 x SE: statistically weak (R-01).
A10: 2024-10-07 | B10: 24.18 | C10: 579.58 | D10: =B10/B9-1 -> -0.073918039 | E10: =C10/C9-1 -> 0.011518727 | F10: =MAX(F9,B10) -> 29.83 | G10: =B10/F10-1 -> -0.18940664 | I10: Std. error of beta | J10: =STEYX(D7:D109,E7:E109)/(STDEV(E7:E109)*SQRT(COUNT(E7:E109)-1)) -> 0.60270766
A11: 2024-10-14 | B11: 28.14 | C11: 584.59 | D11: =B11/B10-1 -> 0.16377171 | E11: =C11/C10-1 -> 0.0086441906 | F11: =MAX(F10,B11) -> 29.83 | G11: =B11/F11-1 -> -0.056654375 | I11: t-statistic | J11: =J9/J10 -> 2.3536958
A12: 2024-10-21 | B12: 25.62 | C12: 579.04 | D12: =B12/B11-1 -> -0.089552239 | E12: =C12/C11-1 -> -0.0094938333 | F12: =MAX(F11,B12) -> 29.83 | G12: =B12/F12-1 -> -0.14113309 | I12: R-squared (systematic share of variance) | J12: =RSQ(D7:D109,E7:E109) -> 0.051998215
A13: 2024-10-28 | B13: 23.85 | C13: 571.04 | D13: =B13/B12-1 -> -0.069086651 | E13: =C13/C12-1 -> -0.013815971 | F13: =MAX(F12,B13) -> 29.83 | G13: =B13/F13-1 -> -0.20046933 | I13: Blume-adjusted beta (used in WACC) | J13: =Inputs!$D$9*J9+(1-Inputs!$D$9) -> 1.2804556 | K13: Blume (1971): 0.67 x raw + 0.33. Chosen over raw/shrinkage - see Review_Log R-01.
A14: 2024-11-04 | B14: 21.99 | C14: 598.19 | D14: =B14/B13-1 -> -0.077987421 | E14: =C14/C13-1 -> 0.04754483 | F14: =MAX(F13,B14) -> 29.83 | G14: =B14/F14-1 -> -0.26282266 | I14: ASTS annualised volatility | J14: =STDEV(D7:D109)*SQRT(52) -> 0.93751899
A15: 2024-11-11 | B15: 24.23 | C15: 585.75 | D15: =B15/B14-1 -> 0.10186448 | E15: =C15/C14-1 -> -0.020796068 | F15: =MAX(F14,B15) -> 29.83 | G15: =B15/F15-1 -> -0.18773047 | I15: SPY annualised volatility | J15: =STDEV(E7:E109)*SQRT(52) -> 0.15070139
A16: 2024-11-18 | B16: 24.1 | C16: 595.51 | D16: =B16/B15-1 -> -0.0053652497 | E16: =C16/C15-1 -> 0.016662399 | F16: =MAX(F15,B16) -> 29.83 | G16: =B16/F16-1 -> -0.1920885 | I16: Idiosyncratic volatility | J16: =J14*SQRT(1-J12) -> 0.91281896
A17: 2024-11-25 | B17: 23.81 | C17: 602.55 | D17: =B17/B16-1 -> -0.012033195 | E17: =C17/C16-1 -> 0.0118218 | F17: =MAX(F16,B17) -> 29.83 | G17: =B17/F17-1 -> -0.20181026 | I17: Max drawdown (2y) | J17: =MIN(G6:G110) -> -0.51455472
A18: 2024-12-02 | B18: 25.32 | C18: 607.81 | D18: =B18/B17-1 -> 0.063418732 | E18: =C18/C17-1 -> 0.008729566 | F18: =MAX(F17,B18) -> 29.83 | G18: =B18/F18-1 -> -0.15119008 | I18: 1-week historical VaR 95% (return) | J18: =PERCENTILE(D7:D109,0.05) -> -0.15690771
A19: 2024-12-09 | B19: 23.48 | C19: 604.21 | D19: =B19/B18-1 -> -0.072669826 | E19: =C19/C18-1 -> -0.0059229035 | F19: =MAX(F18,B19) -> 29.83 | G19: =B19/F19-1 -> -0.21287295 | I19: 1-week CVaR 95% (mean of returns <= VaR) | J19: =AVERAGEIF(D7:D109,"<="&J18) -> -0.17702274
A20: 2024-12-16 | B20: 22.88 | C20: 591.15 | D20: =B20/B19-1 -> -0.025553663 | E20: =C20/C19-1 -> -0.021615001 | F20: =MAX(F19,B20) -> 29.83 | G20: =B20/F20-1 -> -0.23298693 | I20: 1-week parametric VaR 95% (normal) | J20: =AVERAGE(D7:D109)-1.645*STDEV(D7:D109) -> -0.19882201
A21: 2024-12-23 | B21: 22.92 | C21: 595.01 | D21: =B21/B20-1 -> 0.0017482517 | E21: =C21/C20-1 -> 0.0065296456 | F21: =MAX(F20,B21) -> 29.83 | G21: =B21/F21-1 -> -0.23164599 | I21: Annualised downside deviation (MAR 0) | J21: =SQRT(SUMPRODUCT((D7:D109<0)*(D7:D109)^2)/COUNT(D7:D109))*SQRT(52) -> 0.50496483
A22: 2024-12-30 | B22: 23.97 | C22: 591.95 | D22: =B22/B21-1 -> 0.045811518 | E22: =C22/C21-1 -> -0.0051427707 | F22: =MAX(F21,B22) -> 29.83 | G22: =B22/F22-1 -> -0.19644653 | I22: 2-yr high close | J22: =MAX(B6:B110) -> 115.77
A23: 2025-01-06 | B23: 22.37 | C23: 580.49 | D23: =B23/B22-1 -> -0.066750104 | E23: =C23/C22-1 -> -0.019359743 | F23: =MAX(F22,B23) -> 29.83 | G23: =B23/F23-1 -> -0.25008381 | I23: 2-yr low close | J23: =MIN(B6:B110) -> 20.07
A24: 2025-01-13 | B24: 20.78 | C24: 597.58 | D24: =B24/B23-1 -> -0.071077336 | E24: =C24/C23-1 -> 0.029440645 | F24: =MAX(F23,B24) -> 29.83 | G24: =B24/F24-1 -> -0.30338585
A25: 2025-01-21 | B25: 20.35 | C25: 607.97 | D25: =B25/B24-1 -> -0.020692974 | E25: =C25/C24-1 -> 0.017386793 | F25: =MAX(F24,B25) -> 29.83 | G25: =B25/F25-1 -> -0.31780087
A26: 2025-01-27 | B26: 20.24 | C26: 601.82 | D26: =B26/B25-1 -> -0.0054054054 | E26: =C26/C25-1 -> -0.010115631 | F26: =MAX(F25,B26) -> 29.83 | G26: =B26/F26-1 -> -0.32148843
A27: 2025-02-03 | B27: 26.51 | C27: 600.77 | D27: =B27/B26-1 -> 0.30978261 | E27: =C27/C26-1 -> -0.0017447077 | F27: =MAX(F26,B27) -> 29.83 | G27: =B27/F27-1 -> -0.11129735
A28: 2025-02-10 | B28: 32.1 | C28: 609.7 | D28: =B28/B27-1 -> 0.21086382 | E28: =C28/C27-1 -> 0.014864258 | F28: =MAX(F27,B28) -> 32.1 | G28: =B28/F28-1 -> 0
A29: 2025-02-18 | B29: 28.64 | C29: 599.94 | D29: =B29/B28-1 -> -0.10778816 | E29: =C29/C28-1 -> -0.016007873 | F29: =MAX(F28,B29) -> 32.1 | G29: =B29/F29-1 -> -0.10778816
A30: 2025-02-24 | B30: 27.11 | C30: 594.18 | D30: =B30/B29-1 -> -0.053421788 | E30: =C30/C29-1 -> -0.0096009601 | F30: =MAX(F29,B30) -> 32.1 | G30: =B30/F30-1 -> -0.15545171
A31: 2025-03-03 | B31: 33.4 | C31: 575.92 | D31: =B31/B30-1 -> 0.23201771 | E31: =C31/C30-1 -> -0.030731428 | F31: =MAX(F30,B31) -> 33.4 | G31: =B31/F31-1 -> 0
A32: 2025-03-10 | B32: 28.15 | C32: 562.81 | D32: =B32/B31-1 -> -0.15718563 | E32: =C32/C31-1 -> -0.022763578 | F32: =MAX(F31,B32) -> 33.4 | G32: =B32/F32-1 -> -0.15718563
A33: 2025-03-17 | B33: 25.71 | C33: 563.98 | D33: =B33/B32-1 -> -0.086678508 | E33: =C33/C32-1 -> 0.0020788543 | F33: =MAX(F32,B33) -> 33.4 | G33: =B33/F33-1 -> -0.23023952
A34: 2025-03-24 | B34: 24.06 | C34: 555.66 | D34: =B34/B33-1 -> -0.064177363 | E34: =C34/C33-1 -> -0.014752296 | F34: =MAX(F33,B34) -> 33.4 | G34: =B34/F34-1 -> -0.27964072
A35: 2025-03-31 | B35: 20.07 | C35: 505.28 | D35: =B35/B34-1 -> -0.16583541 | E35: =C35/C34-1 -> -0.090666955 | F35: =MAX(F34,B35) -> 33.4 | G35: =B35/F35-1 -> -0.3991018
... A110: 2026-09-08 | B110: 62.42 | C110: 762.4 | D110: =B110/B109-1 -> 0.0017653667 | E110: =C110/C109-1 -> -0.010114387 | F110: =MAX(F109,B110) -> 115.77 | G110: =B110/F110-1 -> -0.4608275

Sheet Calc_Base
A1: MODEL - BASE SCENARIO
A2: Live formulas. Inputs from 'Inputs' column F (scenario) / D (global). $mm unless stated. Periods: 2026H2 stub + 2027-2040; col S = 2041 normalised.
A5: Period | D5: 2026H2 | E5: 2027 | F5: 2028 | G5: 2029 | H5: 2030 | I5: 2031 | J5: 2032 | K5: 2033 | L5: 2034 | M5: 2035 | N5: 2036 | O5: 2037 | P5: 2038 | Q5: 2039 | R5: 2040 | S5: 2041N
A6: Calendar year | B6: yr | D6: 2026 | E6: 2027 | F6: 2028 | G6: 2029 | H6: 2030 | I6: 2031 | J6: 2032 | K6: 2033 | L6: 2034 | M6: 2035 | N6: 2036 | O6: 2037 | P6: 2038 | Q6: 2039 | R6: 2040 | S6: 2041
A7: Period length (years) | B7: yrs | D7: 0.5 | E7: 1 | F7: 1 | G7: 1 | H7: 1 | I7: 1 | J7: 1 | K7: 1 | L7: 1 | M7: 1 | N7: 1 | O7: 1 | P7: 1 | Q7: 1 | R7: 1
A8: Period start (year fraction) | B8: yrs | D8: 2026.5 | E8: 2027 | F8: 2028 | G8: 2029 | H8: 2030 | I8: 2031 | J8: 2032 | K8: 2033 | L8: 2034 | M8: 2035 | N8: 2036 | O8: 2037 | P8: 2038 | Q8: 2039 | R8: 2040
A9: Cash-flow timing (mid-period) | B9: yrs | D9: =D8+D7/2 -> 2026.75 | E9: =E8+E7/2 -> 2027.5 | F9: =F8+F7/2 -> 2028.5 | G9: =G8+G7/2 -> 2029.5 | H9: =H8+H7/2 -> 2030.5 | I9: =I8+I7/2 -> 2031.5 | J9: =J8+J7/2 -> 2032.5 | K9: =K8+K7/2 -> 2033.5 | ... R9: =R8+R7/2 -> 2040.5
A10: CONSTELLATION (Block 2 satellites)
A11: Target fleet, end of period | B11: # | D11: =IF(D$6=2026,Inputs!$F$59,IF(D$6=2027,Inputs!$F$60,IF(D$6=2028,Inputs!$F$61,IF(D$6=2029,Inputs!$F$62,Inputs!$F$63)))) -> 25 | E11: =IF(E$6=2026,Inputs!$F$59,IF(E$6=2027,Inputs!$F$60,IF(E$6=2028,Inputs!$F$61,IF(E$6=2029,Inputs!$F$62,Inputs!$F$63)))) -> 60 | F11: =IF(F$6=2026,Inputs!$F$59,IF(F$6=2027,Inputs!$F$60,IF(F$6=2028,Inputs!$F$61,IF(F$6=2029,Inputs!$F$62,Inputs!$F$63)))) -> 90 | G11: =IF(G$6=2026,Inputs!$F$59,IF(G$6=2027,Inputs!$F$60,IF(G$6=2028,Inputs!$F$61,IF(G$6=2029,Inputs!$F$62,Inputs!$F$63)))) -> 90 | H11: =IF(H$6=2026,Inputs!$F$59,IF(H$6=2027,Inputs!$F$60,IF(H$6=2028,Inputs!$F$61,IF(H$6=2029,Inputs!$F$62,Inputs!$F$63)))) -> 90 | I11: =IF(I$6=2026,Inputs!$F$59,IF(I$6=2027,Inputs!$F$60,IF(I$6=2028,Inputs!$F$61,IF(I$6=2029,Inputs!$F$62,Inputs!$F$63)))) -> 90 | J11: =IF(J$6=2026,Inputs!$F$59,IF(J$6=2027,Inputs!$F$60,IF(J$6=2028,Inputs!$F$61,IF(J$6=2029,Inputs!$F$62,Inputs!$F$63)))) -> 90 | K11: =IF(K$6=2026,Inputs!$F$59,IF(K$6=2027,Inputs!$F$60,IF(K$6=2028,Inputs!$F$61,IF(K$6=2029,Inputs!$F$62,Inputs!$F$63)))) -> 90 | ... R11: =IF(R$6=2026,Inputs!$F$59,IF(R$6=2027,Inputs!$F$60,IF(R$6=2028,Inputs!$F$61,IF(R$6=2029,Inputs!$F$62,Inputs!$F$63)))) -> 90
A12: Beginning fleet | B12: # | D12: =Inputs!$D$28 -> 4 | E12: =D15 -> 25 | F12: =E15 -> 60 | G12: =F15 -> 90 | H12: =G15 -> 90 | I12: =H15 -> 90 | J12: =I15 -> 90 | K12: =J15 -> 90 | L12: =K15 -> 90 | ... R12: =Q15 -> 90
A13: Retirements (end of design life) | B13: # | D13: =0 -> 0 | E13: =IF(E$6-ROUND(Inputs!$D$26,0)=2026,$D$14+Inputs!$D$28,IF(E$6-ROUND(Inputs!$D$26,0)>=2027,INDEX($D$14:D14,1,E$6-ROUND(Inputs!$D$26,0)-2026+1),0)) -> 0 | F13: =IF(F$6-ROUND(Inputs!$D$26,0)=2026,$D$14+Inputs!$D$28,IF(F$6-ROUND(Inputs!$D$26,0)>=2027,INDEX($D$14:E14,1,F$6-ROUND(Inputs!$D$26,0)-2026+1),0)) -> 0 | G13: =IF(G$6-ROUND(Inputs!$D$26,0)=2026,$D$14+Inputs!$D$28,IF(G$6-ROUND(Inputs!$D$26,0)>=2027,INDEX($D$14:F14,1,G$6-ROUND(Inputs!$D$26,0)-2026+1),0)) -> 0 | H13: =IF(H$6-ROUND(Inputs!$D$26,0)=2026,$D$14+Inputs!$D$28,IF(H$6-ROUND(Inputs!$D$26,0)>=2027,INDEX($D$14:G14,1,H$6-ROUND(Inputs!$D$26,0)-2026+1),0)) -> 0 | I13: =IF(I$6-ROUND(Inputs!$D$26,0)=2026,$D$14+Inputs!$D$28,IF(I$6-ROUND(Inputs!$D$26,0)>=2027,INDEX($D$14:H14,1,I$6-ROUND(Inputs!$D$26,0)-2026+1),0)) -> 0 | J13: =IF(J$6-ROUND(Inputs!$D$26,0)=2026,$D$14+Inputs!$D$28,IF(J$6-ROUND(Inputs!$D$26,0)>=2027,INDEX($D$14:I14,1,J$6-ROUND(Inputs!$D$26,0)-2026+1),0)) -> 0 | K13: =IF(K$6-ROUND(Inputs!$D$26,0)=2026,$D$14+Inputs!$D$28,IF(K$6-ROUND(Inputs!$D$26,0)>=2027,INDEX($D$14:J14,1,K$6-ROUND(Inputs!$D$26,0)-2026+1),0)) -> 25 | L13: =IF(L$6-ROUND(Inputs!$D$26,0)=2026,$D$14+Inputs!$D$28,IF(L$6-ROUND(Inputs!$D$26,0)>=2027,INDEX($D$14:K14,1,L$6-ROUND(Inputs!$D$26,0)-2026+1),0)) -> 35 | ... R13: =IF(R$6-ROUND(Inputs!$D$26,0)=2026,$D$14+Inputs!$D$28,IF(R$6-ROUND(Inputs!$D$26,0)>=2027,INDEX($D$14:Q14,1,R$6-ROUND(Inputs!$D$26,0)-2026+1),0)) -> 25
A14: Successful launches (net adds + replacements) | B14: # | D14: =MAX(0,D11-D12+D13) -> 21 | E14: =MAX(0,E11-E12+E13) -> 35 | F14: =MAX(0,F11-F12+F13) -> 30 | G14: =MAX(0,G11-G12+G13) -> 0 | H14: =MAX(0,H11-H12+H13) -> 0 | I14: =MAX(0,I11-I12+I13) -> 0 | J14: =MAX(0,J11-J12+J13) -> 0 | K14: =MAX(0,K11-K12+K13) -> 25 | ... R14: =MAX(0,R11-R12+R13) -> 25
A15: Ending fleet | B15: # | D15: =D12-D13+D14 -> 25 | E15: =E12-E13+E14 -> 60 | F15: =F12-F13+F14 -> 90 | G15: =G12-G13+G14 -> 90 | H15: =H12-H13+H14 -> 90 | I15: =I12-I13+I14 -> 90 | J15: =J12-J13+J14 -> 90 | K15: =K12-K13+K14 -> 90 | ... R15: =R12-R13+R14 -> 90
A16: Satellites built incl. launch losses | B16: # | D16: =D14/(1-Inputs!$D$27) -> 22.105263 | E16: =E14/(1-Inputs!$D$27) -> 36.842105 | F16: =F14/(1-Inputs!$D$27) -> 31.578947 | G16: =G14/(1-Inputs!$D$27) -> 0 | H16: =H14/(1-Inputs!$D$27) -> 0 | I16: =I14/(1-Inputs!$D$27) -> 0 | J16: =J14/(1-Inputs!$D$27) -> 0 | K16: =K14/(1-Inputs!$D$27) -> 26.315789 | ... R16: =R14/(1-Inputs!$D$27) -> 26.315789
A17: Average fleet in orbit | B17: # | D17: =(D12+D15)/2 -> 14.5 | E17: =(E12+E15)/2 -> 42.5 | F17: =(F12+F15)/2 -> 75 | G17: =(G12+G15)/2 -> 90 | H17: =(H12+H15)/2 -> 90 | I17: =(I12+I15)/2 -> 90 | J17: =(J12+J15)/2 -> 90 | K17: =(K12+K15)/2 -> 90 | ... R17: =(R12+R15)/2 -> 90
A18: Unit cost incl. launch ($mm/sat) | B18: $mm | D18: =Inputs!$F$64*(1+Inputs!$F$65)^MAX(0,D$6-2028) -> 22 | E18: =Inputs!$F$64*(1+Inputs!$F$65)^MAX(0,E$6-2028) -> 22 | F18: =Inputs!$F$64*(1+Inputs!$F$65)^MAX(0,F$6-2028) -> 22 | G18: =Inputs!$F$64*(1+Inputs!$F$65)^MAX(0,G$6-2028) -> 22.44 | H18: =Inputs!$F$64*(1+Inputs!$F$65)^MAX(0,H$6-2028) -> 22.8888 | I18: =Inputs!$F$64*(1+Inputs!$F$65)^MAX(0,I$6-2028) -> 23.346576 | J18: =Inputs!$F$64*(1+Inputs!$F$65)^MAX(0,J$6-2028) -> 23.813508 | K18: =Inputs!$F$64*(1+Inputs!$F$65)^MAX(0,K$6-2028) -> 24.289778 | ... R18: =Inputs!$F$64*(1+Inputs!$F$65)^MAX(0,R$6-2028) -> 27.901319
A19: Satellite capex (gross, placed in service) | B19: $mm | D19: =D16*D18 -> 486.31579 | E19: =E16*E18 -> 810.52632 | F19: =F16*F18 -> 694.73684 | G19: =G16*G18 -> 0 | H19: =H16*H18 -> 0 | I19: =I16*I18 -> 0 | J19: =J16*J18 -> 0 | K19: =K16*K18 -> 639.20468 | ... R19: =R16*R18 -> 734.24525
A20: CIP pre-funding pool (scalar, col C) | C20: =Inputs!$D$29*Inputs!$F$66 -> 862.0425
A21: CIP credit applied (already-paid capex) | B21: $mm | D21: =MIN(D19,$C$20) -> 486.31579 | E21: =MIN(E19,$C$20-SUM($D$21:D21)) -> 375.72671 | F21: =MIN(F19,$C$20-SUM($D$21:E21)) -> 0 | G21: =MIN(G19,$C$20-SUM($D$21:F21)) -> 0 | H21: =MIN(H19,$C$20-SUM($D$21:G21)) -> 0 | I21: =MIN(I19,$C$20-SUM($D$21:H21)) -> 0 | J21: =MIN(J19,$C$20-SUM($D$21:I21)) -> 0 | K21: =MIN(K19,$C$20-SUM($D$21:J21)) -> 0 | L21: =MIN(L19,$C$20-SUM($D$21:K21)) -> 0 | ... R21: =MIN(R19,$C$20-SUM($D$21:Q21)) -> 0
A22: Satellite capex, cash | B22: $mm | D22: =D19-D21 -> 0 | E22: =E19-E21 -> 434.79961 | F22: =F19-F21 -> 694.73684 | G22: =G19-G21 -> 0 | H22: =H19-H21 -> 0 | I22: =I19-I21 -> 0 | J22: =J19-J21 -> 0 | K22: =K19-K21 -> 639.20468 | ... R22: =R19-R21 -> 734.24525
A23: REVENUE BUILD
A24: Tier-1 coverage (fraction of partner base) | B24: % | D24: =MIN(1,MAX(0,(D17-Inputs!$D$32)/(Inputs!$D$33-Inputs!$D$32))) -> 0 | E24: =MIN(1,MAX(0,(E17-Inputs!$D$32)/(Inputs!$D$33-Inputs!$D$32))) -> 0.5625 | F24: =MIN(1,MAX(0,(F17-Inputs!$D$32)/(Inputs!$D$33-Inputs!$D$32))) -> 1 | G24: =MIN(1,MAX(0,(G17-Inputs!$D$32)/(Inputs!$D$33-Inputs!$D$32))) -> 1 | H24: =MIN(1,MAX(0,(H17-Inputs!$D$32)/(Inputs!$D$33-Inputs!$D$32))) -> 1 | I24: =MIN(1,MAX(0,(I17-Inputs!$D$32)/(Inputs!$D$33-Inputs!$D$32))) -> 1 | J24: =MIN(1,MAX(0,(J17-Inputs!$D$32)/(Inputs!$D$33-Inputs!$D$32))) -> 1 | K24: =MIN(1,MAX(0,(K17-Inputs!$D$32)/(Inputs!$D$33-Inputs!$D$32))) -> 1 | ... R24: =MIN(1,MAX(0,(R17-Inputs!$D$32)/(Inputs!$D$33-Inputs!$D$32))) -> 1
A25: Tier-2 coverage | B25: % | D25: =MIN(1,MAX(0,(D17-Inputs!$D$34)/(Inputs!$D$35-Inputs!$D$34))) -> 0 | E25: =MIN(1,MAX(0,(E17-Inputs!$D$34)/(Inputs!$D$35-Inputs!$D$34))) -> 0 | F25: =MIN(1,MAX(0,(F17-Inputs!$D$34)/(Inputs!$D$35-Inputs!$D$34))) -> 0.5 | G25: =MIN(1,MAX(0,(G17-Inputs!$D$34)/(Inputs!$D$35-Inputs!$D$34))) -> 1 | H25: =MIN(1,MAX(0,(H17-Inputs!$D$34)/(Inputs!$D$35-Inputs!$D$34))) -> 1 | I25: =MIN(1,MAX(0,(I17-Inputs!$D$34)/(Inputs!$D$35-Inputs!$D$34))) -> 1 | J25: =MIN(1,MAX(0,(J17-Inputs!$D$34)/(Inputs!$D$35-Inputs!$D$34))) -> 1 | K25: =MIN(1,MAX(0,(K17-Inputs!$D$34)/(Inputs!$D$35-Inputs!$D$34))) -> 1 | ... R25: =MIN(1,MAX(0,(R17-Inputs!$D$34)/(Inputs!$D$35-Inputs!$D$34))) -> 1
A26: Logistic steepness k = 2 ln(19) / ramp (col C) | C26: =2*LN(19)/Inputs!$F$72 -> 0.98147966
A27: Tier-1 adoption (take rate of covered subs) | B27: % | D27: =IF(D9>=Inputs!$F$68,Inputs!$F$70/(1+EXP(-$C$26*(D9-(Inputs!$F$68+Inputs!$F$72/2)))),0) -> 0 | E27: =IF(E9>=Inputs!$F$68,Inputs!$F$70/(1+EXP(-$C$26*(E9-(Inputs!$F$68+Inputs!$F$72/2)))),0) -> 0.0079168458 | F27: =IF(F9>=Inputs!$F$68,Inputs!$F$70/(1+EXP(-$C$26*(F9-(Inputs!$F$68+Inputs!$F$72/2)))),0) -> 0.01866055 | G27: =IF(G9>=Inputs!$F$68,Inputs!$F$70/(1+EXP(-$C$26*(G9-(Inputs!$F$68+Inputs!$F$72/2)))),0) -> 0.03797193 | H27: =IF(H9>=Inputs!$F$68,Inputs!$F$70/(1+EXP(-$C$26*(H9-(Inputs!$F$68+Inputs!$F$72/2)))),0) -> 0.06202807 | I27: =IF(I9>=Inputs!$F$68,Inputs!$F$70/(1+EXP(-$C$26*(I9-(Inputs!$F$68+Inputs!$F$72/2)))),0) -> 0.08133945 | J27: =IF(J9>=Inputs!$F$68,Inputs!$F$70/(1+EXP(-$C$26*(J9-(Inputs!$F$68+Inputs!$F$72/2)))),0) -> 0.092083154 | K27: =IF(K9>=Inputs!$F$68,Inputs!$F$70/(1+EXP(-$C$26*(K9-(Inputs!$F$68+Inputs!$F$72/2)))),0) -> 0.096878605 | ... R27: =IF(R9>=Inputs!$F$68,Inputs!$F$70/(1+EXP(-$C$26*(R9-(Inputs!$F$68+Inputs!$F$72/2)))),0) -> 0.099996655
A28: Tier-2 adoption (take rate of covered subs) | B28: % | D28: =IF(D9>=Inputs!$F$69,Inputs!$F$71/(1+EXP(-$C$26*(D9-(Inputs!$F$69+Inputs!$F$72/2)))),0) -> 0 | E28: =IF(E9>=Inputs!$F$69,Inputs!$F$71/(1+EXP(-$C$26*(E9-(Inputs!$F$69+Inputs!$F$72/2)))),0) -> 0 | F28: =IF(F9>=Inputs!$F$69,Inputs!$F$71/(1+EXP(-$C$26*(F9-(Inputs!$F$69+Inputs!$F$72/2)))),0) -> 0 | G28: =IF(G9>=Inputs!$F$69,Inputs!$F$71/(1+EXP(-$C$26*(G9-(Inputs!$F$69+Inputs!$F$72/2)))),0) -> 0.0023750537 | H28: =IF(H9>=Inputs!$F$69,Inputs!$F$71/(1+EXP(-$C$26*(H9-(Inputs!$F$69+Inputs!$F$72/2)))),0) -> 0.0055981649 | I28: =IF(I9>=Inputs!$F$69,Inputs!$F$71/(1+EXP(-$C$26*(I9-(Inputs!$F$69+Inputs!$F$72/2)))),0) -> 0.011391579 | J28: =IF(J9>=Inputs!$F$69,Inputs!$F$71/(1+EXP(-$C$26*(J9-(Inputs!$F$69+Inputs!$F$72/2)))),0) -> 0.018608421 | K28: =IF(K9>=Inputs!$F$69,Inputs!$F$71/(1+EXP(-$C$26*(K9-(Inputs!$F$69+Inputs!$F$72/2)))),0) -> 0.024401835 | ... R28: =IF(R9>=Inputs!$F$69,Inputs!$F$71/(1+EXP(-$C$26*(R9-(Inputs!$F$69+Inputs!$F$72/2)))),0) -> 0.029992857
A29: MNO partner subscriber base (mm) | B29: mm | D29: =Inputs!$D$30*(1+Inputs!$D$51)^MAX(0,D$6-2026) -> 3000 | E29: =Inputs!$D$30*(1+Inputs!$D$51)^MAX(0,E$6-2026) -> 3030 | F29: =Inputs!$D$30*(1+Inputs!$D$51)^MAX(0,F$6-2026) -> 3060.3 | G29: =Inputs!$D$30*(1+Inputs!$D$51)^MAX(0,G$6-2026) -> 3090.903 | H29: =Inputs!$D$30*(1+Inputs!$D$51)^MAX(0,H$6-2026) -> 3121.812 | I29: =Inputs!$D$30*(1+Inputs!$D$51)^MAX(0,I$6-2026) -> 3153.0302 | J29: =Inputs!$D$30*(1+Inputs!$D$51)^MAX(0,J$6-2026) -> 3184.5605 | K29: =Inputs!$D$30*(1+Inputs!$D$51)^MAX(0,K$6-2026) -> 3216.4061 | ... R29: =Inputs!$D$30*(1+Inputs!$D$51)^MAX(0,R$6-2026) -> 3448.4226
A30: Tier-1 paying users (mm, period avg) | B30: mm | D30: =D29*Inputs!$D$31*D24*D27 -> 0 | E30: =E29*Inputs!$D$31*E24*E27 -> 3.3733185 | F30: =F29*Inputs!$D$31*F24*F27 -> 14.27672 | G30: =G29*Inputs!$D$31*G24*G27 -> 29.341888 | H30: =H29*Inputs!$D$31*H24*H27 -> 48.409994 | I30: =I29*Inputs!$D$31*I24*I27 -> 64.116435 | J30: =J29*Inputs!$D$31*J24*J27 -> 73.311093 | K30: =K29*Inputs!$D$31*K24*K27 -> 77.900233 | ... R30: =R29*Inputs!$D$31*R24*R27 -> 86.207683
A31: Tier-2 paying users (mm, period avg) | B31: mm | D31: =D29*(1-Inputs!$D$31)*D25*D28 -> 0 | E31: =E29*(1-Inputs!$D$31)*E25*E28 -> 0 | F31: =F29*(1-Inputs!$D$31)*F25*F28 -> 0 | G31: =G29*(1-Inputs!$D$31)*G25*G28 -> 5.5057956 | H31: =H29*(1-Inputs!$D$31)*H25*H28 -> 13.107314 | I31: =I29*(1-Inputs!$D$31)*I25*I28 -> 26.938494 | J31: =J29*(1-Inputs!$D$31)*J25*J28 -> 44.444731 | K31: =K29*(1-Inputs!$D$31)*K25*K28 -> 58.864658 | ... R31: =R29*(1-Inputs!$D$31)*R25*R28 -> 77.571035
A32: ARPU index (2027 = 1.00) | B32: x | D32: =(1+Inputs!$F$75)^MIN(MAX(0,D$6-2027),Inputs!$D$49-2027)*(1+Inputs!$D$50)^MAX(0,D$6-Inputs!$D$49) -> 1 | E32: =(1+Inputs!$F$75)^MIN(MAX(0,E$6-2027),Inputs!$D$49-2027)*(1+Inputs!$D$50)^MAX(0,E$6-Inputs!$D$49) -> 1 | F32: =(1+Inputs!$F$75)^MIN(MAX(0,F$6-2027),Inputs!$D$49-2027)*(1+Inputs!$D$50)^MAX(0,F$6-Inputs!$D$49) -> 0.99 | G32: =(1+Inputs!$F$75)^MIN(MAX(0,G$6-2027),Inputs!$D$49-2027)*(1+Inputs!$D$50)^MAX(0,G$6-Inputs!$D$49) -> 0.9801 | H32: =(1+Inputs!$F$75)^MIN(MAX(0,H$6-2027),Inputs!$D$49-2027)*(1+Inputs!$D$50)^MAX(0,H$6-Inputs!$D$49) -> 0.970299 | I32: =(1+Inputs!$F$75)^MIN(MAX(0,I$6-2027),Inputs!$D$49-2027)*(1+Inputs!$D$50)^MAX(0,I$6-Inputs!$D$49) -> 0.96059601 | J32: =(1+Inputs!$F$75)^MIN(MAX(0,J$6-2027),Inputs!$D$49-2027)*(1+Inputs!$D$50)^MAX(0,J$6-Inputs!$D$49) -> 0.95099005 | K32: =(1+Inputs!$F$75)^MIN(MAX(0,K$6-2027),Inputs!$D$49-2027)*(1+Inputs!$D$50)^MAX(0,K$6-Inputs!$D$49) -> 0.9652549 | ... R32: =(1+Inputs!$F$75)^MIN(MAX(0,R$6-2027),Inputs!$D$49-2027)*(1+Inputs!$D$50)^MAX(0,R$6-Inputs!$D$49) -> 1.0712832
A33: Tier-1 service revenue | B33: $mm | D33: =D30*Inputs!$F$73*D32*12*D7 -> 0 | E33: =E30*Inputs!$F$73*E32*12*E7 -> 202.39911 | F33: =F30*Inputs!$F$73*F32*12*F7 -> 848.03717 | G33: =G30*Inputs!$F$73*G32*12*G7 -> 1725.4791 | H33: =H30*Inputs!$F$73*H32*12*H7 -> 2818.3301 | I33: =I30*Inputs!$F$73*I32*12*I7 -> 3695.3995 | J33: =J30*Inputs!$F$73*J32*12*J7 -> 4183.0872 | K33: =K30*Inputs!$F$73*K32*12*K7 -> 4511.6149 | ... R33: =R30*Inputs!$F$73*R32*12*R7 -> 5541.1707
A34: Tier-2 service revenue | B34: $mm | D34: =D31*Inputs!$F$74*D32*12*D7 -> 0 | E34: =E31*Inputs!$F$74*E32*12*E7 -> 0 | F34: =F31*Inputs!$F$74*F32*12*F7 -> 0 | G34: =G31*Inputs!$F$74*G32*12*G7 -> 48.566072 | H34: =H31*Inputs!$F$74*H32*12*H7 -> 114.46212 | I34: =I31*Inputs!$F$74*I32*12*I7 -> 232.89309 | J34: =J31*Inputs!$F$74*J32*12*J7 -> 380.39848 | K34: =K31*Inputs!$F$74*K32*12*K7 -> 511.37459 | ... R34: =R31*Inputs!$F$74*R32*12*R7 -> 747.90495
A35: Government revenue | B35: $mm | D35: =IF(D$6=2026,Inputs!$F$78,IF(D$6=2027,Inputs!$F$79,IF(D$6=2028,Inputs!$F$80,IF(D$6=2029,Inputs!$F$81,Inputs!$F$82*(1+Inputs!$F$83)^(D$6-2030))))) -> 45 | E35: =IF(E$6=2026,Inputs!$F$78,IF(E$6=2027,Inputs!$F$79,IF(E$6=2028,Inputs!$F$80,IF(E$6=2029,Inputs!$F$81,Inputs!$F$82*(1+Inputs!$F$83)^(E$6-2030))))) -> 100 | F35: =IF(F$6=2026,Inputs!$F$78,IF(F$6=2027,Inputs!$F$79,IF(F$6=2028,Inputs!$F$80,IF(F$6=2029,Inputs!$F$81,Inputs!$F$82*(1+Inputs!$F$83)^(F$6-2030))))) -> 160 | G35: =IF(G$6=2026,Inputs!$F$78,IF(G$6=2027,Inputs!$F$79,IF(G$6=2028,Inputs!$F$80,IF(G$6=2029,Inputs!$F$81,Inputs!$F$82*(1+Inputs!$F$83)^(G$6-2030))))) -> 220 | H35: =IF(H$6=2026,Inputs!$F$78,IF(H$6=2027,Inputs!$F$79,IF(H$6=2028,Inputs!$F$80,IF(H$6=2029,Inputs!$F$81,Inputs!$F$82*(1+Inputs!$F$83)^(H$6-2030))))) -> 280 | I35: =IF(I$6=2026,Inputs!$F$78,IF(I$6=2027,Inputs!$F$79,IF(I$6=2028,Inputs!$F$80,IF(I$6=2029,Inputs!$F$81,Inputs!$F$82*(1+Inputs!$F$83)^(I$6-2030))))) -> 296.8 | J35: =IF(J$6=2026,Inputs!$F$78,IF(J$6=2027,Inputs!$F$79,IF(J$6=2028,Inputs!$F$80,IF(J$6=2029,Inputs!$F$81,Inputs!$F$82*(1+Inputs!$F$83)^(J$6-2030))))) -> 314.608 | K35: =IF(K$6=2026,Inputs!$F$78,IF(K$6=2027,Inputs!$F$79,IF(K$6=2028,Inputs!$F$80,IF(K$6=2029,Inputs!$F$81,Inputs!$F$82*(1+Inputs!$F$83)^(K$6-2030))))) -> 333.48448 | ... R35: =IF(R$6=2026,Inputs!$F$78,IF(R$6=2027,Inputs!$F$79,IF(R$6=2028,Inputs!$F$80,IF(R$6=2029,Inputs!$F$81,Inputs!$F$82*(1+Inputs!$F$83)^(R$6-2030))))) -> 501.43736
A36: Gateway / product revenue | B36: $mm | D36: =IF(D$6=2026,Inputs!$F$84,IF(D$6=2027,Inputs!$F$85,IF(D$6=2028,Inputs!$F$86,Inputs!$F$87))) -> 83.7 | E36: =IF(E$6=2026,Inputs!$F$84,IF(E$6=2027,Inputs!$F$85,IF(E$6=2028,Inputs!$F$86,Inputs!$F$87))) -> 120 | F36: =IF(F$6=2026,Inputs!$F$84,IF(F$6=2027,Inputs!$F$85,IF(F$6=2028,Inputs!$F$86,Inputs!$F$87))) -> 80 | G36: =IF(G$6=2026,Inputs!$F$84,IF(G$6=2027,Inputs!$F$85,IF(G$6=2028,Inputs!$F$86,Inputs!$F$87))) -> 40 | H36: =IF(H$6=2026,Inputs!$F$84,IF(H$6=2027,Inputs!$F$85,IF(H$6=2028,Inputs!$F$86,Inputs!$F$87))) -> 40 | I36: =IF(I$6=2026,Inputs!$F$84,IF(I$6=2027,Inputs!$F$85,IF(I$6=2028,Inputs!$F$86,Inputs!$F$87))) -> 40 | J36: =IF(J$6=2026,Inputs!$F$84,IF(J$6=2027,Inputs!$F$85,IF(J$6=2028,Inputs!$F$86,Inputs!$F$87))) -> 40 | K36: =IF(K$6=2026,Inputs!$F$84,IF(K$6=2027,Inputs!$F$85,IF(K$6=2028,Inputs!$F$86,Inputs!$F$87))) -> 40 | ... R36: =IF(R$6=2026,Inputs!$F$84,IF(R$6=2027,Inputs!$F$85,IF(R$6=2028,Inputs!$F$86,Inputs!$F$87))) -> 40
A37: Total revenue | B37: $mm | D37: =SUM(D33:D36) -> 128.7 | E37: =SUM(E33:E36) -> 422.39911 | F37: =SUM(F33:F36) -> 1088.0372 | G37: =SUM(G33:G36) -> 2034.0451 | H37: =SUM(H33:H36) -> 3252.7922 | I37: =SUM(I33:I36) -> 4265.0926 | J37: =SUM(J33:J36) -> 4918.0937 | K37: =SUM(K33:K36) -> 5396.474 | ... R37: =SUM(R33:R36) -> 6830.513 | S37: =R37*(1+Inputs!$D$20) -> 7001.2759
A38: Revenue growth (annualised) | B38: % | D38: =IF(Inputs!$D$36=0,0,(D37/D7)/(Inputs!$D$36/0.5)-1) -> 1.7824019 | E38: =IF(D37=0,0,(E37/E7)/(D37/D7)-1) -> 0.64102219 | F38: =IF(E37=0,0,(F37/F7)/(E37/E7)-1) -> 1.575851 | G38: =IF(F37=0,0,(G37/G7)/(F37/F7)-1) -> 0.86946291 | H38: =IF(G37=0,0,(H37/H7)/(G37/G7)-1) -> 0.59917407 | I38: =IF(H37=0,0,(I37/I7)/(H37/H7)-1) -> 0.31120965 | J38: =IF(I37=0,0,(J37/J7)/(I37/I7)-1) -> 0.15310361 | K38: =IF(J37=0,0,(K37/K7)/(J37/J7)-1) -> 0.097269462 | L38: =IF(K37=0,0,(L37/L7)/(K37/K7)-1) -> 0.057007988 | ... R38: =IF(Q37=0,0,(R37/R7)/(Q37/Q7)-1) -> 0.027569965
A39: Paying users per satellite in orbit (mm) | B39: mm | D39: =IF(D17=0,0,(D30+D31)/D17) -> 0 | E39: =IF(E17=0,0,(E30+E31)/E17) -> 0.0793722 | F39: =IF(F17=0,0,(F30+F31)/F17) -> 0.19035627 | G39: =IF(G17=0,0,(G30+G31)/G17) -> 0.38719648 | H39: =IF(H17=0,0,(H30+H31)/H17) -> 0.68352564 | I39: =IF(I17=0,0,(I30+I31)/I17) -> 1.0117214 | J39: =IF(J17=0,0,(J30+J31)/J17) -> 1.308398 | K39: =IF(K17=0,0,(K30+K31)/K17) -> 1.5196099 | ... R39: =IF(R17=0,0,(R30+R31)/R17) -> 1.8197635
A40: OPERATING COSTS & EBITDA
A41: Cost of revenue (gateway + government) | B41: $mm | D41: =D36*(1-Inputs!$D$52)+D35*Inputs!$D$53 -> 95.265 | E41: =E36*(1-Inputs!$D$52)+E35*Inputs!$D$53 -> 149 | F41: =F36*(1-Inputs!$D$52)+F35*Inputs!$D$53 -> 132 | G41: =G36*(1-Inputs!$D$52)+G35*Inputs!$D$53 -> 115 | H41: =H36*(1-Inputs!$D$52)+H35*Inputs!$D$53 -> 136 | I41: =I36*(1-Inputs!$D$52)+I35*Inputs!$D$53 -> 141.88 | J41: =J36*(1-Inputs!$D$52)+J35*Inputs!$D$53 -> 148.1128 | K41: =K36*(1-Inputs!$D$52)+K35*Inputs!$D$53 -> 154.71957 | ... R41: =R36*(1-Inputs!$D$52)+R35*Inputs!$D$53 -> 213.50307
A42: Service variable cost | B42: $mm | D42: =(D33+D34)*Inputs!$F$76 -> 0 | E42: =(E33+E34)*Inputs!$F$76 -> 24.287893 | F42: =(F33+F34)*Inputs!$F$76 -> 101.76446 | G42: =(G33+G34)*Inputs!$F$76 -> 212.88542 | H42: =(H33+H34)*Inputs!$F$76 -> 351.93507 | I42: =(I33+I34)*Inputs!$F$76 -> 471.39511 | J42: =(J33+J34)*Inputs!$F$76 -> 547.61828 | K42: =(K33+K34)*Inputs!$F$76 -> 602.75874 | ... R42: =(R33+R34)*Inputs!$F$76 -> 754.68908
...

Sheet Calc_Bear
A1: MODEL - BEAR SCENARIO
A2: Live formulas. Inputs from 'Inputs' column E (scenario) / D (global). $mm unless stated. Periods: 2026H2 stub + 2027-2040; col S = 2041 normalised.
A5: Period | D5: 2026H2 | E5: 2027 | F5: 2028 | G5: 2029 | H5: 2030 | I5: 2031 | J5: 2032 | K5: 2033 | L5: 2034 | M5: 2035 | N5: 2036 | O5: 2037 | P5: 2038 | Q5: 2039 | R5: 2040 | S5: 2041N
A6: Calendar year | B6: yr | D6: 2026 | E6: 2027 | F6: 2028 | G6: 2029 | H6: 2030 | I6: 2031 | J6: 2032 | K6: 2033 | L6: 2034 | M6: 2035 | N6: 2036 | O6: 2037 | P6: 2038 | Q6: 2039 | R6: 2040 | S6: 2041
A7: Period length (years) | B7: yrs | D7: 0.5 | E7: 1 | F7: 1 | G7: 1 | H7: 1 | I7: 1 | J7: 1 | K7: 1 | L7: 1 | M7: 1 | N7: 1 | O7: 1 | P7: 1 | Q7: 1 | R7: 1
A8: Period start (year fraction) | B8: yrs | D8: 2026.5 | E8: 2027 | F8: 2028 | G8: 2029 | H8: 2030 | I8: 2031 | J8: 2032 | K8: 2033 | L8: 2034 | M8: 2035 | N8: 2036 | O8: 2037 | P8: 2038 | Q8: 2039 | R8: 2040
A9: Cash-flow timing (mid-period) | B9: yrs | D9: =D8+D7/2 -> 2026.75 | E9: =E8+E7/2 -> 2027.5 | F9: =F8+F7/2 -> 2028.5 | G9: =G8+G7/2 -> 2029.5 | H9: =H8+H7/2 -> 2030.5 | I9: =I8+I7/2 -> 2031.5 | J9: =J8+J7/2 -> 2032.5 | K9: =K8+K7/2 -> 2033.5 | ... R9: =R8+R7/2 -> 2040.5
A10: CONSTELLATION (Block 2 satellites)
A11: Target fleet, end of period | B11: # | D11: =IF(D$6=2026,Inputs!$E$59,IF(D$6=2027,Inputs!$E$60,IF(D$6=2028,Inputs!$E$61,IF(D$6=2029,Inputs!$E$62,Inputs!$E$63)))) -> 20 | E11: =IF(E$6=2026,Inputs!$E$59,IF(E$6=2027,Inputs!$E$60,IF(E$6=2028,Inputs!$E$61,IF(E$6=2029,Inputs!$E$62,Inputs!$E$63)))) -> 45 | F11: =IF(F$6=2026,Inputs!$E$59,IF(F$6=2027,Inputs!$E$60,IF(F$6=2028,Inputs!$E$61,IF(F$6=2029,Inputs!$E$62,Inputs!$E$63)))) -> 60 | G11: =IF(G$6=2026,Inputs!$E$59,IF(G$6=2027,Inputs!$E$60,IF(G$6=2028,Inputs!$E$61,IF(G$6=2029,Inputs!$E$62,Inputs!$E$63)))) -> 75 | H11: =IF(H$6=2026,Inputs!$E$59,IF(H$6=2027,Inputs!$E$60,IF(H$6=2028,Inputs!$E$61,IF(H$6=2029,Inputs!$E$62,Inputs!$E$63)))) -> 90 | I11: =IF(I$6=2026,Inputs!$E$59,IF(I$6=2027,Inputs!$E$60,IF(I$6=2028,Inputs!$E$61,IF(I$6=2029,Inputs!$E$62,Inputs!$E$63)))) -> 90 | J11: =IF(J$6=2026,Inputs!$E$59,IF(J$6=2027,Inputs!$E$60,IF(J$6=2028,Inputs!$E$61,IF(J$6=2029,Inputs!$E$62,Inputs!$E$63)))) -> 90 | K11: =IF(K$6=2026,Inputs!$E$59,IF(K$6=2027,Inputs!$E$60,IF(K$6=2028,Inputs!$E$61,IF(K$6=2029,Inputs!$E$62,Inputs!$E$63)))) -> 90 | ... R11: =IF(R$6=2026,Inputs!$E$59,IF(R$6=2027,Inputs!$E$60,IF(R$6=2028,Inputs!$E$61,IF(R$6=2029,Inputs!$E$62,Inputs!$E$63)))) -> 90
A12: Beginning fleet | B12: # | D12: =Inputs!$D$28 -> 4 | E12: =D15 -> 20 | F12: =E15 -> 45 | G12: =F15 -> 60 | H12: =G15 -> 75 | I12: =H15 -> 90 | J12: =I15 -> 90 | K12: =J15 -> 90 | L12: =K15 -> 90 | ... R12: =Q15 -> 90
A13: Retirements (end of design life) | B13: # | D13: =0 -> 0 | E13: =IF(E$6-ROUND(Inputs!$D$26,0)=2026,$D$14+Inputs!$D$28,IF(E$6-ROUND(Inputs!$D$26,0)>=2027,INDEX($D$14:D14,1,E$6-ROUND(Inputs!$D$26,0)-2026+1),0)) -> 0 | F13: =IF(F$6-ROUND(Inputs!$D$26,0)=2026,$D$14+Inputs!$D$28,IF(F$6-ROUND(Inputs!$D$26,0)>=2027,INDEX($D$14:E14,1,F$6-ROUND(Inputs!$D$26,0)-2026+1),0)) -> 0 | G13: =IF(G$6-ROUND(Inputs!$D$26,0)=2026,$D$14+Inputs!$D$28,IF(G$6-ROUND(Inputs!$D$26,0)>=2027,INDEX($D$14:F14,1,G$6-ROUND(Inputs!$D$26,0)-2026+1),0)) -> 0 | H13: =IF(H$6-ROUND(Inputs!$D$26,0)=2026,$D$14+Inputs!$D$28,IF(H$6-ROUND(Inputs!$D$26,0)>=2027,INDEX($D$14:G14,1,H$6-ROUND(Inputs!$D$26,0)-2026+1),0)) -> 0 | I13: =IF(I$6-ROUND(Inputs!$D$26,0)=2026,$D$14+Inputs!$D$28,IF(I$6-ROUND(Inputs!$D$26,0)>=2027,INDEX($D$14:H14,1,I$6-ROUND(Inputs!$D$26,0)-2026+1),0)) -> 0 | J13: =IF(J$6-ROUND(Inputs!$D$26,0)=2026,$D$14+Inputs!$D$28,IF(J$6-ROUND(Inputs!$D$26,0)>=2027,INDEX($D$14:I14,1,J$6-ROUND(Inputs!$D$26,0)-2026+1),0)) -> 0 | K13: =IF(K$6-ROUND(Inputs!$D$26,0)=2026,$D$14+Inputs!$D$28,IF(K$6-ROUND(Inputs!$D$26,0)>=2027,INDEX($D$14:J14,1,K$6-ROUND(Inputs!$D$26,0)-2026+1),0)) -> 20 | L13: =IF(L$6-ROUND(Inputs!$D$26,0)=2026,$D$14+Inputs!$D$28,IF(L$6-ROUND(Inputs!$D$26,0)>=2027,INDEX($D$14:K14,1,L$6-ROUND(Inputs!$D$26,0)-2026+1),0)) -> 25 | ... R13: =IF(R$6-ROUND(Inputs!$D$26,0)=2026,$D$14+Inputs!$D$28,IF(R$6-ROUND(Inputs!$D$26,0)>=2027,INDEX($D$14:Q14,1,R$6-ROUND(Inputs!$D$26,0)-2026+1),0)) -> 20
A14: Successful launches (net adds + replacements) | B14: # | D14: =MAX(0,D11-D12+D13) -> 16 | E14: =MAX(0,E11-E12+E13) -> 25 | F14: =MAX(0,F11-F12+F13) -> 15 | G14: =MAX(0,G11-G12+G13) -> 15 | H14: =MAX(0,H11-H12+H13) -> 15 | I14: =MAX(0,I11-I12+I13) -> 0 | J14: =MAX(0,J11-J12+J13) -> 0 | K14: =MAX(0,K11-K12+K13) -> 20 | ... R14: =MAX(0,R11-R12+R13) -> 20
A15: Ending fleet | B15: # | D15: =D12-D13+D14 -> 20 | E15: =E12-E13+E14 -> 45 | F15: =F12-F13+F14 -> 60 | G15: =G12-G13+G14 -> 75 | H15: =H12-H13+H14 -> 90 | I15: =I12-I13+I14 -> 90 | J15: =J12-J13+J14 -> 90 | K15: =K12-K13+K14 -> 90 | ... R15: =R12-R13+R14 -> 90
A16: Satellites built incl. launch losses | B16: # | D16: =D14/(1-Inputs!$D$27) -> 16.842105 | E16: =E14/(1-Inputs!$D$27) -> 26.315789 | F16: =F14/(1-Inputs!$D$27) -> 15.789474 | G16: =G14/(1-Inputs!$D$27) -> 15.789474 | H16: =H14/(1-Inputs!$D$27) -> 15.789474 | I16: =I14/(1-Inputs!$D$27) -> 0 | J16: =J14/(1-Inputs!$D$27) -> 0 | K16: =K14/(1-Inputs!$D$27) -> 21.052632 | ... R16: =R14/(1-Inputs!$D$27) -> 21.052632
A17: Average fleet in orbit | B17: # | D17: =(D12+D15)/2 -> 12 | E17: =(E12+E15)/2 -> 32.5 | F17: =(F12+F15)/2 -> 52.5 | G17: =(G12+G15)/2 -> 67.5 | H17: =(H12+H15)/2 -> 82.5 | I17: =(I12+I15)/2 -> 90 | J17: =(J12+J15)/2 -> 90 | K17: =(K12+K15)/2 -> 90 | ... R17: =(R12+R15)/2 -> 90
A18: Unit cost incl. launch ($mm/sat) | B18: $mm | D18: =Inputs!$E$64*(1+Inputs!$E$65)^MAX(0,D$6-2028) -> 24 | E18: =Inputs!$E$64*(1+Inputs!$E$65)^MAX(0,E$6-2028) -> 24 | F18: =Inputs!$E$64*(1+Inputs!$E$65)^MAX(0,F$6-2028) -> 24 | G18: =Inputs!$E$64*(1+Inputs!$E$65)^MAX(0,G$6-2028) -> 24.6 | H18: =Inputs!$E$64*(1+Inputs!$E$65)^MAX(0,H$6-2028) -> 25.215 | I18: =Inputs!$E$64*(1+Inputs!$E$65)^MAX(0,I$6-2028) -> 25.845375 | J18: =Inputs!$E$64*(1+Inputs!$E$65)^MAX(0,J$6-2028) -> 26.491509 | K18: =Inputs!$E$64*(1+Inputs!$E$65)^MAX(0,K$6-2028) -> 27.153797 | ... R18: =Inputs!$E$64*(1+Inputs!$E$65)^MAX(0,R$6-2028) -> 32.277332
A19: Satellite capex (gross, placed in service) | B19: $mm | D19: =D16*D18 -> 404.21053 | E19: =E16*E18 -> 631.57895 | F19: =F16*F18 -> 378.94737 | G19: =G16*G18 -> 388.42105 | H19: =H16*H18 -> 398.13158 | I19: =I16*I18 -> 0 | J19: =J16*J18 -> 0 | K19: =K16*K18 -> 571.65889 | ... R19: =R16*R18 -> 679.52277
A20: CIP pre-funding pool (scalar, col C) | C20: =Inputs!$D$29*Inputs!$E$66 -> 775.83825
A21: CIP credit applied (already-paid capex) | B21: $mm | D21: =MIN(D19,$C$20) -> 404.21053 | E21: =MIN(E19,$C$20-SUM($D$21:D21)) -> 371.62772 | F21: =MIN(F19,$C$20-SUM($D$21:E21)) -> 0 | G21: =MIN(G19,$C$20-SUM($D$21:F21)) -> 0 | H21: =MIN(H19,$C$20-SUM($D$21:G21)) -> 0 | I21: =MIN(I19,$C$20-SUM($D$21:H21)) -> 0 | J21: =MIN(J19,$C$20-SUM($D$21:I21)) -> 0 | K21: =MIN(K19,$C$20-SUM($D$21:J21)) -> 0 | L21: =MIN(L19,$C$20-SUM($D$21:K21)) -> 0 | ... R21: =MIN(R19,$C$20-SUM($D$21:Q21)) -> 0
A22: Satellite capex, cash | B22: $mm | D22: =D19-D21 -> 0 | E22: =E19-E21 -> 259.95122 | F22: =F19-F21 -> 378.94737 | G22: =G19-G21 -> 388.42105 | H22: =H19-H21 -> 398.13158 | I22: =I19-I21 -> 0 | J22: =J19-J21 -> 0 | K22: =K19-K21 -> 571.65889 | ... R22: =R19-R21 -> 679.52277
A23: REVENUE BUILD
A24: Tier-1 coverage (fraction of partner base) | B24: % | D24: =MIN(1,MAX(0,(D17-Inputs!$D$32)/(Inputs!$D$33-Inputs!$D$32))) -> 0 | E24: =MIN(1,MAX(0,(E17-Inputs!$D$32)/(Inputs!$D$33-Inputs!$D$32))) -> 0.3125 | F24: =MIN(1,MAX(0,(F17-Inputs!$D$32)/(Inputs!$D$33-Inputs!$D$32))) -> 0.8125 | G24: =MIN(1,MAX(0,(G17-Inputs!$D$32)/(Inputs!$D$33-Inputs!$D$32))) -> 1 | H24: =MIN(1,MAX(0,(H17-Inputs!$D$32)/(Inputs!$D$33-Inputs!$D$32))) -> 1 | I24: =MIN(1,MAX(0,(I17-Inputs!$D$32)/(Inputs!$D$33-Inputs!$D$32))) -> 1 | J24: =MIN(1,MAX(0,(J17-Inputs!$D$32)/(Inputs!$D$33-Inputs!$D$32))) -> 1 | K24: =MIN(1,MAX(0,(K17-Inputs!$D$32)/(Inputs!$D$33-Inputs!$D$32))) -> 1 | ... R24: =MIN(1,MAX(0,(R17-Inputs!$D$32)/(Inputs!$D$33-Inputs!$D$32))) -> 1
A25: Tier-2 coverage | B25: % | D25: =MIN(1,MAX(0,(D17-Inputs!$D$34)/(Inputs!$D$35-Inputs!$D$34))) -> 0 | E25: =MIN(1,MAX(0,(E17-Inputs!$D$34)/(Inputs!$D$35-Inputs!$D$34))) -> 0 | F25: =MIN(1,MAX(0,(F17-Inputs!$D$34)/(Inputs!$D$35-Inputs!$D$34))) -> 0 | G25: =MIN(1,MAX(0,(G17-Inputs!$D$34)/(Inputs!$D$35-Inputs!$D$34))) -> 0.25 | H25: =MIN(1,MAX(0,(H17-Inputs!$D$34)/(Inputs!$D$35-Inputs!$D$34))) -> 0.75 | I25: =MIN(1,MAX(0,(I17-Inputs!$D$34)/(Inputs!$D$35-Inputs!$D$34))) -> 1 | J25: =MIN(1,MAX(0,(J17-Inputs!$D$34)/(Inputs!$D$35-Inputs!$D$34))) -> 1 | K25: =MIN(1,MAX(0,(K17-Inputs!$D$34)/(Inputs!$D$35-Inputs!$D$34))) -> 1 | ... R25: =MIN(1,MAX(0,(R17-Inputs!$D$34)/(Inputs!$D$35-Inputs!$D$34))) -> 1
A26: Logistic steepness k = 2 ln(19) / ramp (col C) | C26: =2*LN(19)/Inputs!$E$72 -> 0.84126828
A27: Tier-1 adoption (take rate of covered subs) | B27: % | D27: =IF(D9>=Inputs!$E$68,Inputs!$E$70/(1+EXP(-$C$26*(D9-(Inputs!$E$68+Inputs!$E$72/2)))),0) -> 0 | E27: =IF(E9>=Inputs!$E$68,Inputs!$E$70/(1+EXP(-$C$26*(E9-(Inputs!$E$68+Inputs!$E$72/2)))),0) -> 0 | F27: =IF(F9>=Inputs!$E$68,Inputs!$E$70/(1+EXP(-$C$26*(F9-(Inputs!$E$68+Inputs!$E$72/2)))),0) -> 0.0044523678 | G27: =IF(G9>=Inputs!$E$68,Inputs!$E$70/(1+EXP(-$C$26*(G9-(Inputs!$E$68+Inputs!$E$72/2)))),0) -> 0.0094055927 | H27: =IF(H9>=Inputs!$E$68,Inputs!$E$70/(1+EXP(-$C$26*(H9-(Inputs!$E$68+Inputs!$E$72/2)))),0) -> 0.018076064 | I27: =IF(I9>=Inputs!$E$68,Inputs!$E$70/(1+EXP(-$C$26*(I9-(Inputs!$E$68+Inputs!$E$72/2)))),0) -> 0.03 | J27: =IF(J9>=Inputs!$E$68,Inputs!$E$70/(1+EXP(-$C$26*(J9-(Inputs!$E$68+Inputs!$E$72/2)))),0) -> 0.041923936 | K27: =IF(K9>=Inputs!$E$68,Inputs!$E$70/(1+EXP(-$C$26*(K9-(Inputs!$E$68+Inputs!$E$72/2)))),0) -> 0.050594407 | ... R27: =IF(R9>=Inputs!$E$68,Inputs!$E$70/(1+EXP(-$C$26*(R9-(Inputs!$E$68+Inputs!$E$72/2)))),0) -> 0.059969118
A28: Tier-2 adoption (take rate of covered subs) | B28: % | D28: =IF(D9>=Inputs!$E$69,Inputs!$E$71/(1+EXP(-$C$26*(D9-(Inputs!$E$69+Inputs!$E$72/2)))),0) -> 0 | E28: =IF(E9>=Inputs!$E$69,Inputs!$E$71/(1+EXP(-$C$26*(E9-(Inputs!$E$69+Inputs!$E$72/2)))),0) -> 0 | F28: =IF(F9>=Inputs!$E$69,Inputs!$E$71/(1+EXP(-$C$26*(F9-(Inputs!$E$69+Inputs!$E$72/2)))),0) -> 0 | G28: =IF(G9>=Inputs!$E$69,Inputs!$E$71/(1+EXP(-$C$26*(G9-(Inputs!$E$69+Inputs!$E$72/2)))),0) -> 0 | H28: =IF(H9>=Inputs!$E$69,Inputs!$E$71/(1+EXP(-$C$26*(H9-(Inputs!$E$69+Inputs!$E$72/2)))),0) -> 0.001113092 | I28: =IF(I9>=Inputs!$E$69,Inputs!$E$71/(1+EXP(-$C$26*(I9-(Inputs!$E$69+Inputs!$E$72/2)))),0) -> 0.0023513982 | J28: =IF(J9>=Inputs!$E$69,Inputs!$E$71/(1+EXP(-$C$26*(J9-(Inputs!$E$69+Inputs!$E$72/2)))),0) -> 0.0045190161 | K28: =IF(K9>=Inputs!$E$69,Inputs!$E$71/(1+EXP(-$C$26*(K9-(Inputs!$E$69+Inputs!$E$72/2)))),0) -> 0.0075 | ... R28: =IF(R9>=Inputs!$E$69,Inputs!$E$71/(1+EXP(-$C$26*(R9-(Inputs!$E$69+Inputs!$E$72/2)))),0) -> 0.014958564
A29: MNO partner subscriber base (mm) | B29: mm | D29: =Inputs!$D$30*(1+Inputs!$D$51)^MAX(0,D$6-2026) -> 3000 | E29: =Inputs!$D$30*(1+Inputs!$D$51)^MAX(0,E$6-2026) -> 3030 | F29: =Inputs!$D$30*(1+Inputs!$D$51)^MAX(0,F$6-2026) -> 3060.3 | G29: =Inputs!$D$30*(1+Inputs!$D$51)^MAX(0,G$6-2026) -> 3090.903 | H29: =Inputs!$D$30*(1+Inputs!$D$51)^MAX(0,H$6-2026) -> 3121.812 | I29: =Inputs!$D$30*(1+Inputs!$D$51)^MAX(0,I$6-2026) -> 3153.0302 | J29: =Inputs!$D$30*(1+Inputs!$D$51)^MAX(0,J$6-2026) -> 3184.5605 | K29: =Inputs!$D$30*(1+Inputs!$D$51)^MAX(0,K$6-2026) -> 3216.4061 | ... R29: =Inputs!$D$30*(1+Inputs!$D$51)^MAX(0,R$6-2026) -> 3448.4226
A30: Tier-1 paying users (mm, period avg) | B30: mm | D30: =D29*Inputs!$D$31*D24*D27 -> 0 | E30: =E29*Inputs!$D$31*E24*E27 -> 0 | F30: =F29*Inputs!$D$31*F24*F27 -> 2.7676962 | G30: =G29*Inputs!$D$31*G24*G27 -> 7.2679437 | H30: =H29*Inputs!$D$31*H24*H27 -> 14.107519 | I30: =I29*Inputs!$D$31*I24*I27 -> 23.647726 | J30: =J29*Inputs!$D$31*J24*J27 -> 33.377327 | K30: =K29*Inputs!$D$31*K24*K27 -> 40.683039 | ... R30: =R29*Inputs!$D$31*R24*R27 -> 51.699716
A31: Tier-2 paying users (mm, period avg) | B31: mm | D31: =D29*(1-Inputs!$D$31)*D25*D28 -> 0 | E31: =E29*(1-Inputs!$D$31)*E25*E28 -> 0 | F31: =F29*(1-Inputs!$D$31)*F25*F28 -> 0 | G31: =G29*(1-Inputs!$D$31)*G25*G28 -> 0 | H31: =H29*(1-Inputs!$D$31)*H25*H28 -> 1.9546109 | I31: =I29*(1-Inputs!$D$31)*I25*I28 -> 5.560522 | J31: =J29*(1-Inputs!$D$31)*J25*J28 -> 10.79331 | K31: =K29*(1-Inputs!$D$31)*K25*K28 -> 18.092284 | ... R31: =R29*(1-Inputs!$D$31)*R25*R28 -> 38.687587
A32: ARPU index (2027 = 1.00) | B32: x | D32: =(1+Inputs!$E$75)^MIN(MAX(0,D$6-2027),Inputs!$D$49-2027)*(1+Inputs!$D$50)^MAX(0,D$6-Inputs!$D$49) -> 1 | E32: =(1+Inputs!$E$75)^MIN(MAX(0,E$6-2027),Inputs!$D$49-2027)*(1+Inputs!$D$50)^MAX(0,E$6-Inputs!$D$49) -> 1 | F32: =(1+Inputs!$E$75)^MIN(MAX(0,F$6-2027),Inputs!$D$49-2027)*(1+Inputs!$D$50)^MAX(0,F$6-Inputs!$D$49) -> 0.98 | G32: =(1+Inputs!$E$75)^MIN(MAX(0,G$6-2027),Inputs!$D$49-2027)*(1+Inputs!$D$50)^MAX(0,G$6-Inputs!$D$49) -> 0.9604 | H32: =(1+Inputs!$E$75)^MIN(MAX(0,H$6-2027),Inputs!$D$49-2027)*(1+Inputs!$D$50)^MAX(0,H$6-Inputs!$D$49) -> 0.941192 | I32: =(1+Inputs!$E$75)^MIN(MAX(0,I$6-2027),Inputs!$D$49-2027)*(1+Inputs!$D$50)^MAX(0,I$6-Inputs!$D$49) -> 0.92236816 | J32: =(1+Inputs!$E$75)^MIN(MAX(0,J$6-2027),Inputs!$D$49-2027)*(1+Inputs!$D$50)^MAX(0,J$6-Inputs!$D$49) -> 0.9039208 | K32: =(1+Inputs!$E$75)^MIN(MAX(0,K$6-2027),Inputs!$D$49-2027)*(1+Inputs!$D$50)^MAX(0,K$6-Inputs!$D$49) -> 0.91747961 | ... R32: =(1+Inputs!$E$75)^MIN(MAX(0,R$6-2027),Inputs!$D$49-2027)*(1+Inputs!$D$50)^MAX(0,R$6-Inputs!$D$49) -> 1.0182601
A33: Tier-1 service revenue | B33: $mm | D33: =D30*Inputs!$E$73*D32*12*D7 -> 0 | E33: =E30*Inputs!$E$73*E32*12*E7 -> 0 | F33: =F30*Inputs!$E$73*F32*12*F7 -> 138.32946 | G33: =G30*Inputs!$E$73*G32*12*G7 -> 355.98679 | H33: =H30*Inputs!$E$73*H32*12*H7 -> 677.17207 | I33: =I30*Inputs!$E$73*I32*12*I7 -> 1112.4074 | J33: =J30*Inputs!$E$73*J32*12*J7 -> 1538.6935 | K33: =K30*Inputs!$E$73*K32*12*K7 -> 1903.6188 | ... R33: =R30*Inputs!$E$73*R32*12*R7 -> 2684.8316
